Workbook

Sheet Banco v2
A1: Linha original | B1: Triagem | C1: Justificativa da triagem | D1: Verificado por (humano) | E1: Data da verificacao | F1: Data | G1: Responsável | H1: Revisor | I1: Status | J1: Ano | K1: Título | L1: DOI | M1: Revista | N1: Espécie | O1: Alvo | P1: Rota de entrega | Q1: Forma do dsRNA | R1: Valor da dose | S1: Unidade da dose | T1: Tempo de exposição | U1: Parâmetro 1 | V1: Valor 1 | W1: Parâmetro 2 | X1: Valor 2 | Y1: Parâmetro 3 | Z1: Valor 3 | AA1: Parâmetro 4 | AB1: Valor 4 | AC1: Parâmetro 5 | AD1: Valor 5 | AE1: Endpoint | AF1: Método da medição | AG1: Grupo controle | AH1: Grau de transferibilidade | AI1: Limitação principal | AJ1: Decisão afetada | AK1: Ação recomendada | AL1: Observações
A2: 2 | B2: 1 - Verificar (prioridade) | C2: Grau 1, D. maidis. Valor qualitativo ('Não significativo'): extrair o valor numerico de fold-change e o p do artigo. | F2: 30/05 | G2: Beatriz | H2: Beatriz | I2: Em análise | J2: 2021 | K2: Assessing the Functionality of RNA Interference (RNAi) in the Phloem-feeding Maize pest Dalbulus maidis | L2: 10.1101/2021.09.29.462424 | M2: bioRxiv | N2: Dalbulus maidis | O2: V-ATPase D | P2: Dieta artificial | Q2: dsRNA nu | R2: 500 | S2: ng/µL | T2: 2 dias | U2: knockdown_alvo | V2: Não significativo | AE2: Análise temporal imediata | AF2: RT-qPCR | AG2: dsGFP | AH2: 1 - Direta | AI2: Curva amostral ainda incompleta para fenótipo final em D. | AJ2: Modelo de latência | AK2: Inserir parâmetro dinâmico para dias > 3. | AL2: Comportamento paralelo à subunidade B demonstrado na curva quantitativa de qPCR. | Desagregado do registro agregado anterior; conferir estágio ninfal, valores e janela temporal no preprint.
A3: 3 | B3: 1 - Verificar (prioridade) | C3: Dado quantitativo mais estrategico do banco (tempo ate floema). Sustenta o gate de E_ing foliar. Conferir Tabela do artigo. | F3: 46059 | G3: Daniel | H3: Beatriz | I3: Em análise | J3: 2021 | K3: Probing behavior of the corn leafhopper Dalbulus maidis on susceptible and resistant maize hybrids | L3: 10.1371/journal.pone.0259481 | M3: PLoS ONE | N3: Dalbulus maidis | O3: EPG | P3: Foliar | T3: 20 h | U3: tempo_ate_floema | V3: 313.97 min | W3: tempo_gasto_floema | X3: ~80% | AE3: Topologia alimentar em var. DK670 | AF3: Electrical Penetration Graph | AG3: DK670 (suscetível) | AH3: 2 - Parcialmente direta | AI3: Inexistem patógenos em avaliação cruzada no estilete elétrico livre. | AJ3: Modelo E_ing foliar | AK3: Invalidar a eficácia primária teórica do spray depositado restrito na epiderme cuticular seca. | AL3: Cigarrinhas exigiram >5h de sondagem para engatar floema plenamente e raramente re-sondaram cutículas cerosas. | Adicionar ao gate de entrega; conferir interpretação exata das ondas e métricas no artigo primário.
A4: 4 | B4: 1 - Verificar (prioridade) | C4: Complementa a linha 3. Valores qualitativos ('Elevada','Presentes') precisam virar numero ou serem marcados como categoricos. | F4: 46059 | G4: Daniel | H4: Beatriz | I4: Em análise | J4: 2021 | K4: Probing behavior of the corn leafhopper Dalbulus maidis on susceptible and resistant maize hybrids | L4: 10.1371/journal.pone.0259481 | M4: PLoS ONE | N4: Dalbulus maidis | O4: EPG | P4: Foliar | T4: 20 h | U4: frequencia_sondagem_mesofilo | V4: Elevada | W4: falhas_ingestao_floematica | X4: Presentes | AE4: Ondas resistivas alimentares Dm1 a Dm5 | AF4: EPG em circuito DC ouro | AG4: DK390 (resistente) | AH4: 2 - Parcialmente direta | AI4: Sem adição de formulação nanoestruturada na lâmina botânica em vivo. | AJ4: Modelo comportamental de restrição de prova | AK4: Tratar o tecido mesofilar em planta resistente como insalubre para sucção. | AL4: Evidenciou ondas Dm1 intensificadas em falhas repetitivas rejeitando fluidos extra-floemáticos rasos superficiais. | Adicionar ao gate de entrega; conferir interpretação exata das ondas e métricas no artigo primário.
A5: 5 | B5: 3 - Nao usar / corrigir | C5: Sem DOI. Rendimento 3,4 ug/mL conflita ~28x com a linha 34 (95 ug/mL) para o mesmo sistema. Identificar a fonte primaria antes de qualquer uso. | F5: 46059 | G5: Daniel | H5: Beatriz | I5: Revisado | J5: 2021 | K5: Scale-up of double-stranded RNA production in fed-batch fermentation... (Citado em PMC8473835) | L5: 10.1186/s12896-015-0226-9 | M5: Journal of Biotechnology | N5: Escherichia coli HT115 | O5: dsRNA amplo | P5: Fermentação | Q5: Plasmídeo interno (L4440) | U5: rendimento_dsRNA | V5: 3.4 µg/mL | AE5: Produtividade do extrato reacional | AF5: Extração fenol-clorofórmio; quantificação por absorbância UV 260 nm | AG5: Comparação com a condição fed-batch da mesma fonte (linha 34, 95.0 µg/mL) | AH5: 4 - Especulativa | AI5: Sistema é E. coli (RNase III−), não B. subtilis; mede rendimento genérico de dsRNA para contexto WSSV/camarão, não eficácia em inseto. | AJ5: Limiar e baseline paramétrica inicial econômica | AK5: Empregar 3-5 ug/mL como cenário pessimista logístico | AL5: Ambos os valores (linhas 5 e 34) são corretos e vêm do mesmo estudo/mesma tabela — não é conflito de dado, é comparação batelada-vs-fed-batch dentro do próprio experimento.
A6: 6 | B6: 1 - Verificar (prioridade) | C6: Melhor dado quantitativo do banco. A estratificacao regional fornece dispersao empirica para a prior de fecundidade basal. | F6: 29/05 | G6: Gabriel | H6: Daniel | I6: Em análise | J6: 2010 | K6: Comparison of Fecundity and Body Size of Mexican and Argentinian Populations of Dalbulus maidis (Hemiptera: Cicadellidae) | L6: doi.org/10.1603/AN09164 | M6: Annals of the Entomological Society of America | N6: Dalbulus maidis / Argentina <1000 m | O6: Fecundidade basal | T6: 5 dias | U6: ovos_por_fêmea | V6: ~20 ovos/fêmea em 5 dias | AE6: Oviposição basal | AF6: Contagem manual de ovos em folhas de milho | AH6: 2 - Parcialmente direta | AI6: Não envolve RNAi nem tratamento molecular / mede apenas baseline populacional | AJ6: Modelo oviposição / baseline de fecundidade | AK6: Usar como prior fraco para fecundidade basal | AL6: Argentina <1000 m
A7: 7 | B7: 2 - Usar com ressalva | C7: Vmax/Km sao Michaelis-Menten, nao decaimento de 1a ordem. ALERTA DE UNIDADE: dose registrada como 500 uM e implausivel; conferir se e uM de nucleotideos ou de moleculas (diferenca de ~10^3). | F7: 29/05 | G7: Nicolas | H7: Daniel | I7: Em análise | J7: 2018 | K7: Biochemical Comparison of dsRNA Degrading Nucleases in Four Different Insects | L7: 10.3389/fphys.2018.00624 | M7: Frontiers in Physiology | N7: Locusta migratoria | O7: dsRNA de EGFP | P7: In vitro | Q7: dsRNA nu | R7: 500 | S7: µM | U7: Vmax | V7: 9.46 µM·s⁻¹ | W7: Km | X7: 3.06 µM | AE7: Atividade nuclease | AF7: Fluorescência | AG7: Tampão | AH7: 4 - Especulativa | AI7: Inseto não sugador e ensaio in vitro / extrapolação forte para D. maidis | AJ7: Modelo k_deg | AK7: Usar apenas qualitativamente | AL7: Útil como cenário de comparação enzimática / não usar como parâmetro direto sem calibração
A8: 8 | B8: 2 - Usar com ressalva | C8: Idem linha 7. Especie nao sugadora, ensaio in vitro. | F8: 29/05 | G8: Nicolas | H8: Daniel | I8: Em análise | J8: 2018 | K8: Biochemical Comparison of dsRNA Degrading Nucleases in Four Different Insects | L8: 10.3389/fphys.2018.00624 | M8: Frontiers in Physiology | N8: Periplaneta americana | O8: dsRNA de EGFP | P8: In vitro | Q8: dsRNA nu | R8: 500 | S8: µM | U8: Vmax | V8: 3.58 µM·s⁻¹ | W8: Km | X8: 0.27 µM | AE8: Atividade nuclease | AF8: Fluorescência | AG8: Tampão | AH8: 4 - Especulativa | AI8: Inseto não sugador e ensaio in vitro / extrapolação forte para D. maidis | AJ8: Modelo k_deg | AK8: Usar apenas qualitativamente | AL8: Útil como cenário de comparação enzimática / não usar como parâmetro direto sem calibração
A9: 9 | B9: 2 - Usar com ressalva | C9: Idem linha 7. Especie nao sugadora, ensaio in vitro. | F9: 29/05 | G9: Nicolas | H9: Daniel | I9: Em análise | J9: 2018 | K9: Biochemical Comparison of dsRNA Degrading Nucleases in Four Different Insects | L9: 10.3389/fphys.2018.00624 | M9: Frontiers in Physiology | N9: Zophobas atratus | O9: dsRNA de EGFP | P9: In vitro | Q9: dsRNA nu | R9: 500 | S9: µM | U9: Vmax | V9: 38.87 µM·s⁻¹ | W9: Km | X9: 17.59 µM | AE9: Atividade nuclease | AF9: Fluorescência | AG9: Tampão | AH9: 4 - Especulativa | AI9: Inseto não sugador e ensaio in vitro / extrapolação forte para D. maidis | AJ9: Modelo k_deg | AK9: Usar apenas qualitativamente | AL9: Útil como cenário de comparação enzimática / não usar como parâmetro direto sem calibração
A10: 10 | B10: 2 - Usar com ressalva | C10: Util para gatilho reprodutivo e modelagem populacional; nao fornece ovos/femea/dia. | F10: 29/05 | G10: Gabriel | H10: Daniel | I10: Em análise | J10: 2025 | K10: Reproductive strategy of overwintering Dalbulus maidis (Hemiptera: Cicadellidae) in subtropical areas: neither temperature nor photoperiod, only corn triggers oviposition | L10: 10.1002/ps.70227 | M10: Pest Management Science | N10: Dalbulus maidis | O10: Oviposição basal / ativação ovariana | P10: Não informado | T10: > 2 semanas | U10: gatilho_da_oviposição | V10: Presença de planta de milho | W10: fertilidade | X10: > 80% por mais de 2 semanas (fêmeas hibernantes, sem machos) | Y10: estado_ovariano | Z10: Ovários inativos mas fertilizados no inverno (quiescência reprodutiva) | AE10: Oviposição (ativação reprodutiva) | AF10: Bioensaio de oviposição / dissecção ovariana | AG10: Fêmeas em diferentes condições (temperatura, fotoperíodo, milho) | AH10: 3 - Indireta | AI10: Foco em fêmeas hibernantes; não fornece ovos/fêmea/dia quantitativo | AJ10: Modelo oviposição / baseline de fecundidade | AK10: Usar como prior fraco | AL10: Útil para modelagem populacional e gatilho reprodutivo; não envolve RNAi.
A11: 11 | B11: 1 - Verificar (prioridade) | C11: Central para k_deg, mas 'degradacao total ~100% em 12h' so define limite inferior de k. Extrair curva temporal se o artigo publicar. | F11: 46059 | G11: Daniel | H11: Gabriel | I11: Revisado | J11: 2023 | K11: Knockdown of double-stranded RNases enhances oral RNA interference in the corn leafhopper | L11: 10.1016/j.pestbp.2023.105618 | M11: Pesticide Biochemistry and Physiology | N11: Dalbulus maidis | O11: dsRNase-2 | P11: In vitro | Q11: dsRNA nu | T11: 12 h | U11: degradacao_saliva | V11: Total (~100%) | AE11: Degradação estrutural de fita RNA | AF11: Gel de degradação | AH11: 1 - Direta | AI11: Não reflete metabolismo dinâmico de produção celular vivo. | AJ11: Modelo k_deg temporal | AK11: Aplicar constante severa nos fluidos gástricos. | AL11: Glândula salivar exibiu degradação profunda em intervalo restrito. | Linha separada para parametrização explícita de degradação ex vivo e estimativa de k_deg.
A12: 12 | B12: 1 - Verificar (prioridade) | C12: Grau 1. Dose de 500 ng/uL e incompativel com escalonamento; usar como teto, nao como faixa operacional. | F12: 30/05 | G12: Beatriz | H12: Gabriel | I12: Revisado | J12: 2021 | K12: Assessing the Functionality of RNA Interference (RNAi) in the Phloem-feeding Maize pest Dalbulus maidis | L12: 10.1101/2021.09.29.462424 | M12: bioRxiv | N12: Dalbulus maidis | O12: V-ATPase B | P12: Dieta artificial | Q12: dsRNA nu | R12: 500 | S12: ng/µL | T12: 4 dias | U12: sobrevivencia | V12: ~16% | W12: deformacao_asa | X12: Alta significância | AE12: Sobrevivência e má-formação ecdise | AF12: Bioensaio visual e microscopia | AG12: dsGFP | AH12: 1 - Direta | AI12: Dose exagerada incompatível com escalonamento puro de produção. | AJ12: Desenho experimental de viabilidade | AK12: Ajustar limiar EC50 agressivo do letal agudo. | AL12: A deformação aguda foi corroborada pelo teste chi-quadrado. | Desagregado do registro agregado anterior; conferir estágio ninfal, valores e janela temporal no preprint.
A13: 13 | B13: 1 - Verificar (prioridade) | C13: Grau 1. Conferir se a diferenca B vs D e estatisticamente sustentada. | F13: 30/05 | G13: Beatriz | H13: Gabriel | I13: Revisado | J13: 2021 | K13: Assessing the Functionality of RNA Interference (RNAi) in the Phloem-feeding Maize pest Dalbulus maidis | L13: 10.1101/2021.09.29.462424 | M13: bioRxiv | N13: Dalbulus maidis | O13: V-ATPase D | P13: Dieta artificial | Q13: dsRNA nu | R13: 500 | S13: ng/µL | T13: 4 dias | U13: sobrevivencia | V13: ~18% | W13: deformacao_asa | X13: Não significativa | AE13: Mortalidade letal direta | AF13: Bioensaio em ninfas de quinto instar | AG13: dsGFP | AH13: 1 - Direta | AI13: Fenótipo anômalo não obteve robustez estatística. | AJ13: Escolha do alvo preferencial inter-subunidades | AK13: Avançar com modelo de sobrevivência para subunidade B como superior à D. | AL13: Diferença sutil no impacto pós-muda em relação ao grupo tratado B. | Desagregado do registro agregado anterior; conferir estágio ninfal, valores e janela temporal no preprint.
A14: 14 | B14: 1 - Verificar (prioridade) | C14: Grau 1, janela temporal curta. Sustenta hipotese de latencia (t_delay), nao de ausencia de efeito. | F14: 30/05 | G14: Beatriz | H14: Gabriel | I14: Revisado | J14: 2021 | K14: Assessing the Functionality of RNA Interference (RNAi) in the Phloem-feeding Maize pest Dalbulus maidis | L14: 10.1101/2021.09.29.462424 | M14: bioRxiv | N14: Dalbulus maidis | O14: V-ATPase B | P14: Dieta artificial | Q14: dsRNA nu | R14: 500 | S14: ng/µL | T14: 2 dias | U14: knockdown_alvo | V14: Não significativo | AE14: Análise temporal imediata de redução de transcrito | AF14: RT-qPCR | AG14: dsGFP | AH14: 1 - Direta | AI14: Restrito apenas à janela inicial não-cumulativa. | AJ14: Modelo de latência temporal (t_delay) | AK14: Definir falha no decaimento expressivo nas primeiras 48h da simulação preditiva. | AL14: Confirma atraso intrínseco e sistemático no espraiamento celular de transcritos V-ATPase. | Desagregado do registro agregado anterior; conferir estágio ninfal, valores e janela temporal no preprint.
A15: 15 | B15: 2 - Usar com ressalva | C15: Contexto ecologico (mortalidade natural de ovos). Nao usar em decisao de potencia molecular. | F15: 28/05 | G15: Marcos | H15: Jhenifer | I15: Em análise | J15: 2009 | K15: Egg Parasitoids of Dalbulus maidis (Hemiptera: Cicadellidae) in Jalisco State, Mexico | L15: 10.1653/024.092.0316 | M15: Florida Entomologist | N15: Dalbulus maidis | O15: Parasitismo natural de ovos | P15: Coleta de ovos sentinela em campo | T15: 72–96 h de exposição em campo; ovos com menos de 24 h | U15: ovos_expostos | V15: aproximadamente 1600 ovos sentinela | W15: parasitoides_emergidos | X15: 923 vespas emergidas | Y15: parasitoides_identificados | Z15: 5 táxons: Anagrus breviphragma; Polynema sp.; Paracentrobia nr subflava; Aphelinoidea sp.; Pseudoligosita sp. | AA15: local_coleta | AB15: Zapopan e El Grullo, Jalisco, México | AC15: distribuição_por_local | AD15: El Grullo: 419 parasitoides; Zapopan: 504 parasitoides | AE15: Emergência e identificação de parasitoides de ovos | AF15: Exposição de ovos sentinela em plantas de milho; incubação de folhas em laboratório; emergência de adultos; identificação taxonômica | AG15: Não há controle experimental clássico; estudo observacional com ovos sentinela | AH15: 2 - Parcialmente direta | AI15: A taxa real de parasitismo não foi medida; estudo feito no México; não envolve RNAi, BicC, dsRNase-2 ou entrega por Bacillus | AJ15: Modelo oviposição-população; mortalidade natural de ovos; incerteza ecológica basal | AK15: Usar como prior fraco para mortalidade natural de ovos; não usar como taxa direta de parasitismo sem validação
A16: 16 | B16: 2 - Usar com ressalva | C16: Responde diretamente a questao da RNase III no chassi: B. subtilis dRncS produz dsRNA funcional. Mas C. elegans e bacterivoro; nao transfere para hemiptero. | F16: 28/05 | G16: Marcos | H16: Jhenifer | I16: Em análise | J16: 2015 | K16: Specific RNA Interference in Caenorhabditis elegans by Ingested dsRNA Expressed in Bacillus subtilis | L16: 10.1371/journal.pone.0124508 | M16: PLoS ONE | N16: Bacillus subtilis; Caenorhabditis elegans | O16: GFP transgênico; DAF-16::GFP; SUR-5::GFP | P16: Bactéria oral; alimentação em placa NGM contendo B. subtilis recombinante | Q16: dsRNA bacteriano produzido em B. subtilis ΔrncS por vetor pBSR-GFP com promotores Pspac bidirecionais | T16: 24 h de alimentação | U16: animais_com_redução_GFP | V16: aproximadamente 90–95% dos animais | W16: GFP_DAF16_residual | X16: 3% da expressão original | Y16: redução_GFP_SUR5 | Z16: quase 6 vezes menor | AA16: IPTG_indução | AB16: 2 mM em placas NGM-RNAi | AC16: fragmento_GFP | AD16: 750 bp | AE16: Knockdown funcional de GFP por RNAi após ingestão de B. subtilis expressando dsRNA | AF16: Alimentação bacteriana; microscopia de fluorescência; quantificação por ImageJ; comparação estatística por t-test | AG16: B. subtilis BG322 com vetor pBSR vazio/original | AH16: 4 - Especulativa | AI16: C. elegans é bacterívoro e ingere/tritura bactérias diretamente; não representa alimentação estiletar de Dalbulus maidis; não mede BicC, dsRNase-2, oviposição, esporo foliar, milho tratado nem dose absoluta de dsRNA | AJ16: Biofábrica; desenho do chassi; gate de payload; hipótese de entrega bacteriana | AK16: Usar como evidência de que B. subtilis ΔrncS pode expressar dsRNA funcional; não usar como prova de entrega em D. maidis; medir payload_dsRNA no chassi BioGuard e testar ingestão/recuperação em cigarrinha antes de assumir eficácia | AL16: Verificar em Materials and Methods: construção pBSR, fragmento GFP de 750 bp, B. subtilis BG322 ΔrncS e indução por IPTG; verificar em Results/Fig. 2: queda de GFP após ingestão. O artigo sustenta biofábrica bacteriana em modelo distante, mas não valida Bacillus foliar/esporulado para Dalbulus maidis.
A17: 17 | B17: 1 - Verificar (prioridade) | C17: Ver linha 6. | F17: 29/05 | G17: Gabriel | H17: Jhenifer | I17: Em análise | J17: 2010 | K17: Comparison of Fecundity and Body Size of Mexican and Argentinian Populations of Dalbulus maidis (Hemiptera: Cicadellidae) | L17: 10.1603/AN09164 | M17: Annals of the Entomological Society of America | N17: Dalbulus maidis / México >1000 m | O17: Fecundidade basal | T17: 5 dias | U17: ovos_por_fêmea | V17: ~26 ovos/fêmea em 5 dias | AE17: Oviposição basal | AF17: Contagem manual de ovos em folhas de milho | AH17: 2 - Parcialmente direta | AI17: Não envolve RNAi nem tratamento molecular / mede apenas baseline populacional | AJ17: Modelo oviposição / baseline de fecundidade | AK17: Usar como prior fraco para fecundidade basal | AL17: México >1000 m
A18: 18 | B18: 1 - Verificar (prioridade) | C18: Ver linha 6. | F18: 29/05 | G18: Gabriel | H18: Jhenifer | I18: Em análise | J18: 2010 | K18: Comparison of Fecundity and Body Size of Mexican and Argentinian Populations of Dalbulus maidis (Hemiptera: Cicadellidae) | L18: 10.1603/AN09164 | M18: Annals of the Entomological Society of America | N18: Dalbulus maidis / México <1000 m | O18: Fecundidade basal | T18: 5 dias | U18: ovos_por_fêmea | V18: ~13 ovos/fêmea em 5 dias | AE18: Oviposição basal | AF18: Contagem manual de ovos em folhas de milho | AH18: 2 - Parcialmente direta | AI18: Não envolve RNAi nem tratamento molecular / mede apenas baseline populacional | AJ18: Modelo oviposição / baseline de fecundidade | AK18: Usar como prior fraco para fecundidade basal | AL18: México <1000 m
A19: 19 | B19: 1 - Verificar (prioridade) | C19: Ver linha 6. | F19: 29/05 | G19: Gabriel | H19: Jhenifer | I19: Em análise | J19: 2010 | K19: Comparison of Fecundity and Body Size of Mexican and Argentinian Populations of Dalbulus maidis (Hemiptera: Cicadellidae) | L19: 10.1603/AN09164 | M19: Annals of the Entomological Society of America | N19: Dalbulus maidis / Argentina >1000 m | O19: Fecundidade basal | T19: 5 dias | U19: ovos_por_fêmea | V19: ~20 ovos/fêmea em 5 dias | AE19: Oviposição basal | AF19: Contagem manual de ovos em folhas de milho | AH19: 2 - Parcialmente direta | AI19: Não envolve RNAi nem tratamento molecular / mede apenas baseline populacional | AJ19: Modelo oviposição / baseline de fecundidade | AK19: Usar como prior fraco para fecundidade basal | AL19: Argentina >1000 m
A20: 20 | B20: 1 - Verificar (prioridade) | C20: Rota de injecao contorna a barreira luminal. Substituir 'aprox. 0 ovos' por valor numerico e n. | F20: 30/05 | G20: Sofia | H20: Marcos | I20: Em análise | J20: 2022 | K20: Development of efficient RNAi methods in the corn leafhopper Dalbulus maidis | L20: 10.1002/ps.6937 | M20: Pest Management Science | N20: Dalbulus maidis | O20: BicC | P20: Injeção | Q20: dsRNA nu | R20: 100 | S20: ng/µL | T20: 7 dias | U20: ovos_por_fêmea | V20: ~0 ovos | W20: sobrevivência | X20: 0.9 | AE20: Oviposição letal (fecundidade) | AF20: Contagem manual e microscopia | AG20: dsGFP | AH20: 2 - Parcialmente direta | AI20: Método contorna a barreira do trato digestivo e não avalia via oral. | AJ20: Escolha do alvo | AK20: Validar capacidade em rota oral. | AL20: Dose induziu parada reprodutiva e fenótipo ovariano opaco/abortivo. | Consolidado com o registro previamente preenchido por Sofia; conferir valores no artigo primário.
A21: 21 | B21: 1 - Verificar (prioridade) | C21: Mesma penetrancia da linha 20 com o dobro da dose: sugere saturacao. Relevante para EC50/Emax. | F21: 30/05 | G21: Sofia | H21: Marcos | I21: Em análise | J21: 2022 | K21: Development of efficient RNAi methods in the corn leafhopper Dalbulus maidis | L21: 10.1002/ps.6937 | M21: Pest Management Science | N21: Dalbulus maidis | O21: BicC | P21: Injeção | Q21: dsRNA nu | R21: 200 | S21: ng/µL | T21: 7 dias | U21: ovos_por_fêmea | V21: ~0 ovos | W21: sobrevivência | X21: 0.9 | AE21: Oviposição letal (fecundidade) | AF21: Contagem manual e microscopia | AG21: dsGFP | AH21: 2 - Parcialmente direta | AI21: Injeção não comprova captação estiletar. | AJ21: Modelo dose-resposta | AK21: Comparar com as doses intra-abdominais menores. | AL21: Atingiu penetrância idêntica à dose de 100 ng/µL. | Consolidado com o registro previamente preenchido por Sofia; conferir valores no artigo primário.
A22: 22 | B22: 1 - Verificar (prioridade) | C22: Grau 1, rota oral. 'Alta reducao' precisa virar fold-change numerico. Linha critica para dose-resposta oral. | F22: 30/05 | G22: Sofia | H22: Marcos | I22: Em análise | J22: 2022 | K22: Development of efficient RNAi methods in the corn leafhopper Dalbulus maidis | L22: 10.1002/ps.6937 | M22: Pest Management Science | N22: Dalbulus maidis | O22: BicC | P22: Dieta artificial | Q22: dsRNA nu | R22: 200 | S22: ng/µL | T22: 3 dias | U22: knockdown_BicC | V22: Alta redução | AE22: Knockdown de transcrito | AF22: RT-qPCR | AG22: dsGFP | AH22: 1 - Direta | AI22: Dieta contorna dificuldades do mesofilo foliar. | AJ22: Faixa de dose inicial | AK22: Adotar como teto no ensaio in vitro. | AL22: Exposição de 3 dias de alimentação confirmada por EPG breve. | Consolidado com o registro previamente preenchido por Sofia; conferir valores no artigo primário.
A23: 23 | B23: 1 - Verificar (prioridade) | C23: Grau 1, rota oral. 'Queda drastica' precisa virar valor. Linha critica para dose-resposta oral. | F23: 46059 | G23: Daniel | H23: Marcos | I23: Em análise | J23: 2022 | K23: Development of efficient RNAi methods in the corn leafhopper Dalbulus maidis | L23: 10.1002/ps.6937 | M23: Pest Management Science | N23: Dalbulus maidis | O23: BicC | P23: Dieta artificial | Q23: dsRNA nu | R23: 100 | S23: ng/µL | T23: 3 dias | U23: knockdown_BicC | V23: Queda drástica | AE23: Knockdown de transcrito | AF23: RT-qPCR | AG23: dsGFP | AH23: 1 - Direta | AI23: Não testa Bacillus em folha real. | AJ23: Faixa de dose inicial | AK23: Usar no modelo dose-resposta oral. | AL23: Bioensaio confinado por parafilm. Valor quantitativo não numérico no resumo. | Nova condição separada do registro didático de 48 h; conferir valor quantitativo no artigo primário.
A24: 24 | B24: 2 - Usar com ressalva | C24: Hemiptero, rota planta transgenica. Prior fraco para RNAi oral. | F24: 28/05 | G24: Nicolas | H24: Mariana | I24: Em análise | J24: 2011 | K24: Knockdown of Midgut Genes by dsRNA-Transgenic Plant-Mediated RNA Interference in the Hemipteran Insect Nilaparvata lugens | L24: 10.1371/journal.pone.0020504 | M24: PLoS ONE | N24: Nilaparvata lugens | O24: Nicar | P24: Planta transgênica | Q24: Planta expressando dsRNA | T24: 2 a 4 dias | U24: knockdown_alvo | V24: 42.1%–43.3% | W24: mortalidade | X24: Não observado | AE24: Knockdown de transcrito | AF24: qRT-PCR / Northern blot | AG24: WT / vetor vazio | AH24: 3 - Indireta | AI24: Outro hemíptero e rota planta-transgênica / não informa dose absoluta ingerida | AJ24: Rota de entrega / controle experimental | AK24: Usar como prior fraco para RNAi oral em hemípteros | AL24: O dado sustenta que planta pode entregar dsRNA funcional em hemíptero sugador, mas não valida Bacillus foliar
A25: 25 | B25: 2 - Usar com ressalva | C25: Idem linha 24. Padronizar grafia do alvo (Nitry / Nltry). | F25: 28/05 | G25: Nicolas | H25: Mariana | I25: Em análise | J25: 2011 | K25: Knockdown of Midgut Genes by dsRNA-Transgenic Plant-Mediated RNA Interference in the Hemipteran Insect Nilaparvata lugens | L25: 10.1371/journal.pone.0020504 | M25: PLoS ONE | N25: Nilaparvata lugens | O25: Nitry | P25: Planta transgênica | Q25: Planta expressando dsRNA | T25: 2 a 4 dias | U25: knockdown_alvo | V25: 61%–73.3% | W25: mortalidade | X25: Não observado | AE25: Knockdown de transcrito | AF25: qRT-PCR / Northern blot | AG25: WT / vetor vazio | AH25: 3 - Indireta | AI25: Outro hemíptero e rota planta-transgênica / não informa dose absoluta ingerida | AJ25: Rota de entrega / controle experimental | AK25: Usar como prior fraco para RNAi oral em hemípteros | AL25: O dado sustenta que planta pode entregar dsRNA funcional em hemíptero sugador, mas não valida Bacillus foliar | Conferir se o valor máximo do intervalo corresponde especificamente ao quarto dia.
A26: 26 | B26: 2 - Usar com ressalva | C26: Artigo revisado e mudado pra "usar com ressalva" | F26: 28/05 | G26: Nicolas | H26: Mariana | I26: Revisado | J26: 2021 | K26: Optimizing Efficient RNAi-Mediated Control of Hemipteran Pests (Psyllids, Leafhoppers, Whitefly): Modified Pyrimidines in dsRNA Triggers | L26: https://doi.org/10.3390/plants10091782 | M26: Plants for MDPI | N26: Diaphorina citri (Hemiptera: Liviidae) | O26: Cactin | P26: Foliar | Q26: dsRNA com pirimidinas modificadas (2'-F-Citosina / 2'-F-Uracila, ~30–55% de substituição) | R26: 2 | S26: µg/planta | T26: 8 dias | U26: mortalidade_adultos | V26: 58.8% ± SE 0.64 (n=9) | AE26: Mortalidade | AF26: Bioensaio de mortalidade; ANOVA one-way + Tukey post-hoc (p<0.05) | AG26: dsRNA-CSBV (2 µg, controle não relacionado): 21.4% ± SE 0.66; controle água | AH26: 3 - Indireta | AI26: Psilídeo (não cigarrinha); spray tópico direto em citros (não dieta artificial); resultado é 1 de várias condições/espécies/genes do artigo (também testa B. tabaci e H. vitripennis, e genes Trehalase e Syntaxin1A, não capturados nesta linha). | AJ26: Faixa de dose / forma do dsRNA | AK26: Usar como evidência indireta de que pirimidinas modificadas (2'-F) aumentam mortalidade ~13 pontos percentuais vs. dsRNA não-modificado no mesmo alvo/dose em Hemiptera; não extrapolar valor absoluto de mortalidade para D. maidis. | AL26: µg/planta" (dose total por muda em spray tópico) não está no vocabulário controlado de Unidade da dose (que é todo em concentração/dose por inseto); mantive por ser o mais fiel ao artigo, mas não é diretamente comparável a doses em ng/µL de outras linhas
A27: 27 | B27: 2 - Usar com ressalva | C27: Controle positivo de maquinaria RNAi. Parametros registrados sao de desenho experimental, nao de efeito. | F27: 28/05 | G27: Nicolas | H27: Mariana | I27: Em análise | J27: 2012 | K27: Molecular characterization and gene functional analysis of Dicer-2 gene from Nilaparvata lugens | L27: 10.1111/j.1744-7917.2012.01539.x | M27: Insect Science | N27: Nilaparvata lugens | O27: NlDcr-2 | P27: Dieta artificial | Q27: dsRNA nu | R27: 500 | S27: ng/µL | T27: 4 dias | U27: n_indivíduos | V27: 25 ninfas | W27: volume_dieta_total | X27: 40 µL | AE27: Knockdown de transcrito | AF27: RT-PCR convencional / qRT-PCR | AG27: dsGFP | AH27: 3 - Indireta | AI27: Outro hemíptero / endpoint molecular sem oviposição | AJ27: Faixa de dose / controle positivo de maquinaria RNAi | AK27: Usar como faixa inicial e controle positivo em hemíptero sugador | AL27: A linha existente na planilha não preserva valor quantitativo de knockdown / retornar ao artigo para extrair a curva | Confirmar ano bibliográfico final e extrair valor quantitativo de knockdown.
A28: 28 | B28: 2 - Usar com ressalva | C28: Riboswitches: relevante para engenharia de expressao no chassi, nao para RNAi. | F28: 28/05 | G28: Tales | H28: Mariana | I28: Em análise | J28: 2021 | K28: Targeting riboswitches with synthetic small RNAs for metabolic engineering | L28: 10.1101/2021.06.21.449321 | M28: bioRxiv | N28: Bacillus subtilis | O28: Riboswitches (purE, pbuE, xpt, ribDG) | P28: Fermentação | Q28: sRNA sintético | U28: ativação da expressão (pbuE) | V28: 103 vezes | W28: aumento da riboflavina (ribDG) | X28: 0,5 | Y28: aumento com operon de sRNAs | Z28: 5 vezes | AE28: Ativação da expressão gênica (luciferase/bioluminescência); produção de riboflavina | AF28: Ensaio de luciferase in vitro; bioluminescência in vivo (luxABCDE); HPLC para riboflavina | AG28: Cepa B. subtilis sem sRNA (parental) | AH28: 4 - Especulativa | AI28: Espécie diferente de D. maidis; tecnologia de sRNA para ativação de genes, não RNAi para knockdown; não envolve dsRNA nem entrega oral a inseto | AJ28: Biofábrica | AK28: Não usar em modelo | AL28: Útil para engenharia do chassi; não sustenta entrega nem eficácia de RNAi em inseto.
A29: 29 | B29: 3 - Nao usar / corrigir | C29: Sem parametro, sem endpoint, sem grau atribuido. | F29: 21/05 | G29: Daniel | H29: Nicolas | I29: Revisado | J29: 2022 | K29: Probiotics expressing double-stranded RNA targeting VP28 efficiently protect shrimps from WSSV infection | L29: 10.1016/j.aqrep.2022.101067 | M29: Aquaculture Reports | N29: Litopenaeus vannamei | O29: VP28 (gene estrutural do vírus WSSV; alvo do dsRNA hairpin) | P29: Bactéria oral (probiótico administrado por imersão em água do tanque, 1x/dia por 5 dias, antes de desafio oral com WSSV) | Q29: dsRNA bacteriano (hairpin dsVP28, vetor pWH1520, expresso em Lactobacillus plantarum ou Lactococcus lactis) | R29: 4,5 × 10¹⁰ | S29: CFU/2 L | T29: 5 dias de imersão com probiótico; mortalidade acumulada avaliada até 5 dias pós-infecção (dpi) | U29: mortalidade_cumulativa (100X ds-L. lactis, 5 dpi) | V29: 0.33 | W29: carga_viral_WSSV (log cópias, 3 dpi) | X29: 2.88 ± 0.18 (vs. 6.28 ± 0.61 no grupo positivo sem probiótico) | AE29: Mortalidade | AF29: Contagem diária de sobreviventes; qPCR de carga viral; qRT-PCR de expressão gênica | AG29: Grupo positivo (desafiado com WSSV, sem probiótico) e L. lactis selvagem sem dsVP28 na mesma dose (69% de mortalidade) | AH29: 4 - Especulativa | AI29: Camarão (crustáceo aquático); entrega via probiótico por imersão em água — mecanismo de administração muito distante de inseto terrestre sugador. | AJ29: Biofábrica / prova de conceito de entrega bacteriana de dsRNA | AK29: Usar apenas como evidência qualitativa de que bactérias probióticas (Lactobacillus/Lactococcus) podem expressar dsRNA funcional e reduzir mortalidade viral; não extrapolar valores quantitativos para D. maidis/Bacillus sem validação própria. | AL29: Manter separado do estudo de ScienceAsia; conferir método, endpoint e grupo controle no artigo primário.
A30: 30 | B30: 3 - Nao usar / corrigir | C30: Campo 'Rota de entrega' contem texto gerado sem correspondencia com o vocabulario controlado. Reextrair da fonte. | F30: 25/05 | G30: Daniel | H30: Nicolas | I30: Revisado | J30: 2020 | K30: Bacillus subtilis expressing dsVP28 improved shrimp survival from WSSV challenge | L30: 10.2306/scienceasia1513-1874.2020.s003 | M30: ScienceAsia | N30: Bacillus subtilis | O30: VP28 | P30: Bactéria oral (aditivo via água/ração restrita em aquário limpo esterilizado de teste isolado zoológico comparativo patológico marinho) | Q30: dsRNA bacteriano (hairpin dsVP28 do plasmídeo pBE:cDNA4 em B. subtilis) | U30: taxa_sobrevivencia_grupo | V30: 0.917 (91.7%, aos 7 dpi — cai para 0.292 (29.2%) aos 14 dpi) | AE30: Sobrevivência imunológica e letalidade crônica do WSSV viral circulante inter-peneídeo em grupo | AF30: Contagem diária de sobreviventes (bioensaio de sobrevivência) | AG30: Controle positivo = dieta comercial sem B. subtilis, desafiado com WSSV (28.6% de sobrevivência aos 7 dpi; 9.5% aos 14 dpi). NÃO é grupo injetado — a injeção é um experimento diferente do mesmo artigo. | AH30: 4 - Especulativa | AI30: Organismo biológico crustáceo difere absolutamente no modo e via nutricional estática em relação a todo arquétipo inseto e em relação a estilete. | AJ30: Validação do potencial da biofábrica industrial | AK30: Reconhecer que se o esporo puder infiltrar a seiva e atravessar as dsRNases ele suportaria proteção imunológica plena. | AL30: Ratificou a preservação conformacional celular das cepas de bacilo na ausência de RNase e indução segura da proteção letal contínua de grupo experimental fechado. | Consolidado a partir do registro incompleto previamente existente. Conferir artigo primário antes do uso quantitativo.
A31: 31 | B31: 3 - Nao usar / corrigir | C31: Corrigido | F31: 26/05 | G31: Nicolas | H31: Nicolas | I31: Revisado | J31: 2024 | K31: A spray-induced gene silencing strategy for Spodoptera frugiperda oviposition inhibition using nanomaterial-encapsulated dsEcR | L31: https://doi.org/10.1016/j.ijbiomac.2024.136503 | M31: International Journal of Biological Macromolecules | N31: Spodoptera frugiperda | O31: dsEcR | P31: Foliar | Q31: nanopartícula | R31: 1000 + | S31: ng/µL | T31: 72 horas | U31: redução_ovos_por_fêmea | V31: ~44% vs. controle dsGFP/SPc (72h pós-pulverização) | AE31: Oviposição | AF31: qRT-PCR (transcrito EcR); contagem de ovos por fêmea | AG31: dsGFP/SPc/detergente (mantém). O artigo também compara com dsEcR/DEPC/detergente (sem nanopartícula), mostrando que o SPc é necessário para o efeito. | AH31: 4 - Especulativa | AI31: Lepidóptero mastigador; sistema de entrega distante da alimentação estiletar de D. maidis | AJ31: Forma do dsRNA / estabilidade ambiental | AK31: Usar apenas qualitativamente
A32: 32 | B32: 2 - Usar com ressalva | C32: Hemiptero, planta transgenica. Prior fraco. | F32: 28/05 | G32: Nicolas | H32: Nicolas | I32: Em análise | J32: 2011 | K32: Knockdown of Midgut Genes by dsRNA-Transgenic Plant-Mediated RNA Interference in the Hemipteran Insect Nilaparvata lugens | L32: 10.1371/journal.pone.0020504 | M32: PLoS ONE | N32: Nilaparvata lugens | O32: NIHT1 | P32: Planta transgênica | Q32: Planta expressando dsRNA | T32: 2 a 4 dias | U32: knockdown_alvo | V32: 42.7%–59.3% | W32: mortalidade | X32: Não observado | AE32: Knockdown de transcrito | AF32: qRT-PCR / Northern blot | AG32: WT / vetor vazio | AH32: 3 - Indireta | AI32: Outro hemíptero e rota planta-transgênica / não informa dose absoluta ingerida | AJ32: Rota de entrega / controle experimental | AK32: Usar como prior fraco para RNAi oral em hemípteros | AL32: O dado sustenta que planta pode entregar dsRNA funcional em hemíptero sugador, mas não valida Bacillus foliar
A33: 33 | B33: 2 - Usar com ressalva | C33: Michaelis-Menten em lepidoptero. Mesmo alerta de unidade das linhas 7-9. | F33: 29/05 | G33: Nicolas | H33: Sofia | I33: Em análise | J33: 2018 | K33: Biochemical Comparison of dsRNA Degrading Nucleases in Four Different Insects | L33: 10.3389/fphys.2018.00624 | M33: Frontiers in Physiology | N33: Spodoptera litura | O33: dsRNA de EGFP | P33: In vitro | Q33: dsRNA nu | R33: 500 | S33: µM | T33: 25 min | U33: Vmax | V33: 13.4 µM·s⁻¹ | W33: Km | X33: 2.28 µM | AE33: Atividade nuclease | AF33: Fluorescência | AG33: Tampão | AH33: 4 - Especulativa | AI33: Inseto não sugador e ensaio in vitro / extrapolação forte para D. maidis | AJ33: Modelo k_deg | AK33: Usar apenas qualitativamente | AL33: Útil como cenário de comparação enzimática / não usar como parâmetro direto sem calibração
A34: 34 | B34: 3 - Nao usar / corrigir | C34: Campo 'Endpoint' contem texto gerado. Alem disso, 95 ug/mL conflita ~28x com a linha 5. Reextrair. | F34: 46059 | G34: Daniel | H34: Sofia | I34: Revisado | J34: 2015 | K34: Large-scale production and antiviral efficacy of multi-target double-stranded RNA for the prevention of white spot syndrome virus (WSSV) in shrimp | L34: 10.1186/s12896-015-0226-9 | M34: BMC Biotechnology | N34: Escherichia coli HT115 | O34: dsRNA amplo | P34: Fermentação (fed-batch, alimentação contínua de glicerol, 30 h, biorreator 10 L, meio TB) | Q34: Plasmídeo interno (vetor hairpin derivado de pDrive; NÃO é L4440 — não confirmado no artigo) | U34: rendimento_dsRNA | V34: 95.0 ± 21.5 µg/mL | AE34: Produtividade de dsRNA em fermentação fed-batch (30 h, biorreator 10 L, alimentação com glicerol, meio TB) — ~30x a batelada | AF34: Extração fenol e quantificação ótica UV | AG34: Fermentação em batelada (linha 5), mesmo biorreator de 10 L | AH34: 4 - Especulativa | AI34: Linhagem microbiana imprópria com fins filosóficos industriais e não agro-compatível. | AJ34: Gate de Titer-alvo do Biofábrica e payload | AK34: Estipular alvos volumétricos da fermentação de Bacillus baseados neste salto de 30x por hipernutrição contínua celular controlada. | AL34: Demonstra a maleabilidade elástica massiva inerente das colônias mutadas sob regime exato e suprimento de nitrogênio rico basal para bioconversão dsRNA direto. | Fonte incompleta no relatório; identificar título integral, autores, ano e DOI antes do uso quantitativo.
A35: 35 | B35: 2 - Usar com ressalva | C35: Campos corrigidos e preenchidos e colocado em "usar como ressalva" | F35: 46059 | G35: Daniel | H35: Sofia | I35: Revisado | J35: 2020 | K35: RNA Interference Is Enhanced by Knockdown of Double-Stranded RNases in the Yellow Fever Mosquito Aedes aegypti | L35: 10.3390/insects11060327 | M35: Insects | N35: Aedes aegypti | O35: Gus | P35: In vitro (ensaio ex vivo com extrato de intestino médio dissecado) | Q35: dsRNA nu | R35: 100 | S35: ng | T35: 60 min | U35: tempo_degradacao_total | V35: Não verificável como "4 min" — texto do artigo relata apenas que o extrato de intestino normal degrada quase todo o dsRNA em ≤30 min, e que após knockdown de dsRNase (ds4103) não há degradação significativa até 60 min. Valor numérico preciso exigiria digitalização da Figura 3 (WebPlotDigitizer) por um humano. | AE35: Mortalidade | AF35: Análise gel e espectro | AG35: Eletroforese em gel de agarose 1.5%; intensidade de banda relativa (software Image Lab); teste de Wilcoxon rank-sum vs. controle dsDsRed | AH35: 3 - Indireta | AI35: Mosquito hematófago (Diptera), não Hemiptera; ensaio é ex vivo com extrato de intestino de larva dissecado (não com o inseto vivo intacto); a cinética exata de degradação (k_deg) não pôde ser confirmada em texto — só a tendência qualitativa (ver Valor 1). | AJ35: Modelo cinético de degradação (k_deg) por dsRNase intestinal | AK35: Prover taxa limitante grave nos modelos onde RNase livre circula pelo meio líquido gástrico ativo em contato sem proteção. | AL35: Destruição quase imediata enfatiza risco contundente em expor a dupla fita frágil fosfodiéster ao banho ácido intestinal livre basal do mosquito. | Usar como cenário comparativo; não transferir diretamente para D. maidis sem calibração.
A36: 36 | B36: 3 - Nao usar / corrigir | C36: Campo 'Endpoint' contem texto gerado. Valor 0.77 sem unidade: fracao? taxa? indeterminado. | F36: 46059 | G36: Daniel | H36: Sofia | I36: Revisado | J36: 2022 | K36: Cloning and functional characterization of a double-stranded RNA-degrading nuclease in the tawny crazy ant | L36: 10.3389/fphys.2022.833652 | M36: Frontiers in Physiology | N36: Nylanderia fulva | O36: dsGFP | P36: In vitro | Q36: dsRNA nu | R36: 200 | S36: ng | T36: 2 h | U36: degradacao_midgut | V36: 0.77 (77% degradado; 23% remanescente após 2 h de incubação com fluido do intestino médio) | AE36: Quebra de matriz in vitro lenta sob a óptica proteica enzimática parcial residual luminal ant nest biológica operária | AF36: Eletroforese em gel; quantificação por intensidade de banda relativa | AG36: Controle negativo (0h, sem incubação) e positivo (2h); degradação bloqueada por EDTA ou por calor+SDS, confirmando dependência de cátion divalente | AH36: 4 - Especulativa | AI36: Formiga (Hymenoptera, dieta generalista/detritívora) é taxonomicamente muito distante de D. maidis (Hemiptera, dieta floemática); ensaio é ex vivo com fluido de intestino extraído, não com o inseto vivo. | AJ36: Coeficiente k_deg (taxa de degradação) para o modelo de estabilidade do payload | AK36: Equacionar a perda de 3/4 do payload ao fim da janela estomacal crítica inicial e exigir carreador de fuga. | AL36: Exibe atividade consideravelmente mais branda perante dípteros confirmando que insetos possuem velocidades e cinéticas variadas singulares de depuração RNAi gástrica. | Usar como cenário comparativo; não transferir diretamente para D. maidis sem calibração.
A37: 37 | B37: 1 - Verificar (prioridade) | C37: Dado central: reducao de 23,6x em dsRNase-2 e melhora do RNAi oral. Alta prioridade de verificacao e extracao quantitativa. | F37: 25/05 | G37: Beatriz | H37: Tales | I37: Em análise | J37: 2023 | K37: Knockdown of double-stranded RNases enhances oral RNA interference in the corn leafhopper | L37: 10.1016/j.pestbp.2023.105618 | M37: Pesticide Biochemistry and Physiology | N37: Dalbulus maidis | O37: dsRNase-2 | P37: Injeção seguida de dieta artificial | Q37: dsRNA nu | R37: 200 | S37: ng/µL | T37: 48 h de pré-tratamento + 3 dias de dieta oral | U37: knockdown_dsRNase2 | V37: Redução 23.6x | W37: melhora_RNAi_oral | X37: Alta | AE37: Aumento da penetrância do alvo secundário | AF37: RT-qPCR e Bioensaio fenotípico | AG37: dsGFP isolado | AH37: 2 - Parcialmente direta | AI37: Injeção inviável agronomicamente como etapa primária preparatória. | AJ37: Teste de co-entrega e modelo Mix-T | AK37: Modelar dsRNAs quiméricos duplos para supressão salivar. | AL37: Consolidação do registro original de Beatriz. Glândulas salivares promoveram degradação completa do dsRNA em até 12 h; intestino médio em 12–24 h. A etapa preparatória por injeção limita a extrapolação agronômica.
A38: 38 | B38: 2 - Usar com ressalva | C38: Manter esta como a linha canonica de Psylliodes; consolidar 39 e 40 aqui. | F38: 26/05 | G38: Nicolas | H38: Tales | I38: Em análise | J38: 2025 | K38: DsRNA-based carriers with pH-tuneable release kinetics for effective control of Psylliodes chrysocephala | L38: https://doi.org/10.1016/j.ijbiomac.2025.149697 | M38: International Journal of Biological Macromolecules | N38: Psylliodes chrysocephala | O38: dsProsβ6 | P38: Foliar | Q38: dsRNA nu | R38: 100 | S38: ng/µL | T38: 15 Dias | U38: Sobrevivência (Mortalidade) aos 15 dias | V38: Caiu para 36,6% | W38: Cinética de Liberação | X38: Não se aplica (o dsRNA já se encontra livre na solução) | Y38: Proteção contra Calor (Estresse Térmico a 40°C) | Z38: Baixa; mostrou degradação extensiva após apenas 4 horas de exposição | AA38: Proteção contra Radiação UV | AB38: Baixa; rápida degradação em menos de 4 horas | AE38: Sobrevivência (efeito letal) e Inibição da alimentação / Consumo de folhas (efeito comportamental/subletal) | AF38: Bioensaio foliar / ensaio de estabilidade térmica/UV | AG38: dsGFP | AH38: 4 - Especulativa | AI38: Coleóptero mastigador em rota foliar; fisiologia alimentar distante de D. maidis | AJ38: Forma do dsRNA / estabilidade ambiental | AK38: Usar apenas qualitativamente | AL38: dsRNA livre em solução
A39: 39 | B39: 3 - Nao usar / corrigir | C39: Duplicata da linha 38 (mesmo valor de sobrevivencia). Consolidar. | F39: 46168 | G39: Nicolas | H39: Tales | I39: Em análise | J39: 2025 | K39: DsRNA-based carriers with pH-tuneable release kinetics for effective control of Psylliodes chrysocephala | L39: https://doi.org/10.1016/j.ijbiomac.2025.149697 | M39: International Journal of Biological Macromolecules | N39: Psylliodes chrysocephala | O39: dsProsβ6 | P39: Foliar | Q39: nanopartícula / liberação rápida sensível a pH | R39: 100 | S39: ng/µL | T39: 15 Dias | U39: Sobrevivência (Mortalidade) aos 15 dias | V39: Caiu para 36,6% | W39: Cinética de Liberação | X39: Rápida e responsiva ao pH; foi aproximadamente uma ordem de grandeza mais rápida que a sílica | Y39: Proteção contra Calor (Estresse Térmico a 40°C) | Z39: Alta; manteve o dsRNA intacto por até 16 horas de exposição | AA39: Proteção contra Radiação UV | AB39: Moderada; os sinais de degradação começaram a aparecer após 6 horas | AE39: Sobrevivência (efeito letal) e Inibição da alimentação / Consumo de folhas (efeito comportamental/subletal) | AF39: Bioensaio foliar / ensaio de estabilidade térmica/UV | AG39: dsGFP | AH39: 4 - Especulativa | AI39: Coleóptero mastigador em rota foliar; fisiologia alimentar distante de D. maidis | AJ39: Forma do dsRNA / estabilidade ambiental | AK39: Usar apenas qualitativamente | AL39: carreador rápido
A40: 40 | B40: 3 - Nao usar / corrigir | C40: Duplicata da linha 38 (mesmo valor de sobrevivencia). Consolidar. | F40: 46168 | G40: Nicolas | H40: Tales | I40: Em análise | J40: 2025 | K40: DsRNA-based carriers with pH-tuneable release kinetics for effective control of Psylliodes chrysocephala | L40: https://doi.org/10.1016/j.ijbiomac.2025.149697 | M40: International Journal of Biological Macromolecules | N40: Psylliodes chrysocephala | O40: dsProsβ6 | P40: Foliar | Q40: nanopartícula / liberação lenta bifásica | R40: 100 | S40: ng/µL | T40: 15 Dias | U40: Sobrevivência (Mortalidade) aos 15 dias | V40: Caiu para 36,6% | W40: Cinética de Liberação | X40: Lenta e bifásica; controlada por difusão devido ao tamanho restrito dos poros (8 nm) do carreador | Y40: Proteção contra Calor (Estresse Térmico a 40°C) | Z40: Alta; manteve o dsRNA intacto por até 12 horas de exposição | AA40: Proteção contra Radiação UV | AB40: Moderada; os sinais de degradação começaram a aparecer após 6 horas | AE40: Sobrevivência (efeito letal) e Inibição da alimentação / Consumo de folhas (efeito comportamental/subletal) | AF40: Bioensaio foliar / ensaio de estabilidade térmica/UV | AG40: dsGFP | AH40: 4 - Especulativa | AI40: Coleóptero mastigador em rota foliar; fisiologia alimentar distante de D. maidis | AJ40: Forma do dsRNA / estabilidade ambiental | AK40: Usar apenas qualitativamente | AL40: carreador lento; poros de 8 nm descritos no registro original
...

Sheet Parametros (long)
A1: id | B1: Linha origem | C1: Triagem | D1: Especie | E1: Alvo | F1: Rota de entrega | G1: Parametro | H1: Valor original (texto) | I1: valor_num | J1: unidade | K1: incerteza_tipo | L1: incerteza_valor | M1: n | N1: Tempo / condicao | O1: Grau de transferibilidade | P1: sigma_log10 | Q1: usar_em_modelo | R1: modo | S1: DOI | T1: Verificado por (humano) | U1: Data da verificacao | V1: Observacao
A2: P001 | B2: 2 | C2: 2 - Usar com ressalva | D2: Dalbulus maidis | E2: V-ATPase D | F2: Dieta artificial | G2: knockdown_alvo | H2: Não significativo | N2: Coletas em 2 dias e 4 dias pós alimentação; efeito robusto apenas no dia 4; temperatura 23–25 °C, fotoperíodo 14:10 | O2: 1 - Direta | P2: =IFERROR(IF(LEFT(O2,1)="1",0.1,IF(LEFT(O2,1)="2",0.25,IF(LEFT(O2,1)="3",0.5,IF(LEFT(O2,1)="4",1,"")))),"") -> 0.1 | Q2: sim (qualitativo) | R2: literatura | S2: 10.1101/2021.09.29.462424 | T2: Beatriz Venancio | U2: 46302 | V2: CORREÇÔES: tempo/condição. Tempo de efeito: O knockdown dos genes V ATPase B e D só se tornou significativo após 4 dias de ingestão contínua de dsRNA, não em 2 dias. Isso mostra que o RNAi em Dalbulus maidis exige exposição prolongada para se consolidar. Além da redução da expressão, houve mortalidade aumentada e deformações nas asas nos insetos tratados, reforçando que o knockdown teve impacto funcional. O efeito não foi imediato – sugere exposição prolongada
A3: P002 | B3: 3 | C3: 2 - Usar com ressalva | D3: Dalbulus maidis | E3: EPG | F3: Foliar | G3: tempo_ate_floema | H3: 316.6 (Página 7, tabela 2) | I3: 316.6 | J3: min | N3: 20 h | O3: 2 - Parcialmente direta | P3: =IFERROR(IF(LEFT(O3,1)="1",0.1,IF(LEFT(O3,1)="2",0.25,IF(LEFT(O3,1)="3",0.5,IF(LEFT(O3,1)="4",1,"")))),"") -> 0.25 | Q3: sim | R3: literatura | S3: 10.1371/journal.pone.0259481 | T3: Nicolas Blaskovski | U3: 46302
A4: P003 | B4: 3 | C4: 2 - Usar com ressalva | D4: Dalbulus maidis | E4: EPG | F4: Foliar | G4: tempo_gasto_floema | H4: ~80% (Não consegui identificar) | I4: 80 | J4: % | N4: 20 h | O4: 2 - Parcialmente direta | P4: =IFERROR(IF(LEFT(O4,1)="1",0.1,IF(LEFT(O4,1)="2",0.25,IF(LEFT(O4,1)="3",0.5,IF(LEFT(O4,1)="4",1,"")))),"") -> 0.25 | Q4: sim | R4: literatura | S4: 10.1371/journal.pone.0259481 | T4: Beatriz Venancio | U4: 46267
A5: P004 | B5: 4 | C5: 2 - Usar com ressalva | D5: Dalbulus maidis | E5: EPG | F5: Foliar | G5: frequencia_sondagem_mesofilo | H5: Elevada (Página 6 a 8 - Figura 3/ Tabela 2) | N5: 20 h | O5: 2 - Parcialmente direta | P5: =IFERROR(IF(LEFT(O5,1)="1",0.1,IF(LEFT(O5,1)="2",0.25,IF(LEFT(O5,1)="3",0.5,IF(LEFT(O5,1)="4",1,"")))),"") -> 0.25 | Q5: sim | R5: literatura | S5: 10.1371/journal.pone.0259481 | T5: Beatriz Venancio | U5: 46267
A6: P005 | B6: 4 | C6: 2 - Usar com ressalva | D6: Dalbulus maidis | E6: EPG | F6: Foliar | G6: falhas_ingestao_floematica | H6: Presentes | N6: 20 h | O6: 2 - Parcialmente direta | P6: =IFERROR(IF(LEFT(O6,1)="1",0.1,IF(LEFT(O6,1)="2",0.25,IF(LEFT(O6,1)="3",0.5,IF(LEFT(O6,1)="4",1,"")))),"") -> 0.25 | Q6: sim | R6: literatura | S6: 10.1371/journal.pone.0259481 | T6: Beatriz Venancio | U6: 46267
A7: P006 | B7: 5 | C7: 3 - Nao usar / corrigir | D7: Escherichia coli HT115 | E7: dsRNA amplo | F7: Fermentação | G7: rendimento_dsRNA | H7: 3.4 ± 0.5 µg/mL | I7: 3.4 | J7: µg/mL | O7: 4 - Especulativa | P7: =IFERROR(IF(LEFT(O7,1)="1",0.1,IF(LEFT(O7,1)="2",0.25,IF(LEFT(O7,1)="3",0.5,IF(LEFT(O7,1)="4",1,"")))),"") -> 1 | R7: literatura | S7: 10.1186/s12896-015-0226-9 | T7: Nicolas
A8: P007 | B8: 6 | C8: 1 - Verificar (prioridade) | D8: Dalbulus maidis / Argentina <1000 m | E8: Fecundidade basal | G8: ovos_por_fêmea | H8: ~20 ovos/fêmea em 5 dias (Página 2, paragrafo 2 - 20 Ovos, figura 1) | I8: 20 | J8: ovos/fêmea em 5 dias | N8: 5 dias | O8: 2 - Parcialmente direta | P8: =IFERROR(IF(LEFT(O8,1)="1",0.1,IF(LEFT(O8,1)="2",0.25,IF(LEFT(O8,1)="3",0.5,IF(LEFT(O8,1)="4",1,"")))),"") -> 0.25 | R8: literatura | S8: 10.1603/AN09164 | T8: Beatriz Venancio | U8: 46267
A9: P008 | B9: 7 | C9: 2 - Usar com ressalva | D9: Locusta migratoria | E9: dsRNA de EGFP | F9: In vitro | G9: Vmax | H9: 9.46 µM·s⁻¹ (Página 7 - Saturation Curves and Enzyme Kinetics) | I9: 9.46 | J9: µM·s⁻¹ | O9: 4 - Especulativa | P9: =IFERROR(IF(LEFT(O9,1)="1",0.1,IF(LEFT(O9,1)="2",0.25,IF(LEFT(O9,1)="3",0.5,IF(LEFT(O9,1)="4",1,"")))),"") -> 1 | R9: literatura | S9: 10.3389/fphys.2018.00624
A10: P009 | B10: 7 | C10: 2 - Usar com ressalva | D10: Locusta migratoria | E10: dsRNA de EGFP | F10: In vitro | G10: Km | H10: 3.06 µM (Página 10 - Discussion) | I10: 3.06 | J10: µM | O10: 4 - Especulativa | P10: =IFERROR(IF(LEFT(O10,1)="1",0.1,IF(LEFT(O10,1)="2",0.25,IF(LEFT(O10,1)="3",0.5,IF(LEFT(O10,1)="4",1,"")))),"") -> 1 | R10: literatura | S10: 10.3389/fphys.2018.00624
A11: P010 | B11: 8 | C11: 2 - Usar com ressalva | D11: Periplaneta americana | E11: dsRNA de EGFP | F11: In vitro | G11: Vmax | H11: 3.58 µM·s⁻¹ (Página 7 - Saturation Curves and Enzyme Kinetics) | I11: 3.58 | J11: µM·s⁻¹ | O11: 4 - Especulativa | P11: =IFERROR(IF(LEFT(O11,1)="1",0.1,IF(LEFT(O11,1)="2",0.25,IF(LEFT(O11,1)="3",0.5,IF(LEFT(O11,1)="4",1,"")))),"") -> 1 | R11: literatura | S11: 10.3389/fphys.2018.00624
A12: P011 | B12: 8 | C12: 2 - Usar com ressalva | D12: Periplaneta americana | E12: dsRNA de EGFP | F12: In vitro | G12: Km | H12: 0.27 µM (Página 7 - Saturation Curves and Enzyme Kinetics) | I12: 0.27 | J12: µM | O12: 4 - Especulativa | P12: =IFERROR(IF(LEFT(O12,1)="1",0.1,IF(LEFT(O12,1)="2",0.25,IF(LEFT(O12,1)="3",0.5,IF(LEFT(O12,1)="4",1,"")))),"") -> 1 | R12: literatura | S12: 10.3389/fphys.2018.00624
A13: P012 | B13: 9 | C13: 2 - Usar com ressalva | D13: Zophobas atratus | E13: dsRNA de EGFP | F13: In vitro | G13: Vmax | H13: 38.87 µM·s⁻¹ (Página 7 - Saturaion Curves and Enzymatic | I13: 38.87 | J13: µM·s⁻¹ | O13: 4 - Especulativa | P13: =IFERROR(IF(LEFT(O13,1)="1",0.1,IF(LEFT(O13,1)="2",0.25,IF(LEFT(O13,1)="3",0.5,IF(LEFT(O13,1)="4",1,"")))),"") -> 1 | R13: literatura | S13: 10.3389/fphys.2018.00624
A14: P013 | B14: 9 | C14: 2 - Usar com ressalva | D14: Zophobas atratus | E14: dsRNA de EGFP | F14: In vitro | G14: Km | H14: 17.59 μM | I14: 17.59 | J14: µM | O14: 4 - Especulativa | P14: =IFERROR(IF(LEFT(O14,1)="1",0.1,IF(LEFT(O14,1)="2",0.25,IF(LEFT(O14,1)="3",0.5,IF(LEFT(O14,1)="4",1,"")))),"") -> 1 | R14: literatura | S14: 10.3389/fphys.2018.00624
A15: P014 | B15: 10 | C15: 2 - Usar com ressalva | D15: Dalbulus maidis | E15: Oviposição basal / ativação ovariana | F15: Não informado | G15: gatilho_da_oviposição | H15: Presença de planta de milho | N15: > 2 semanas | O15: 3 - Indireta | P15: =IFERROR(IF(LEFT(O15,1)="1",0.1,IF(LEFT(O15,1)="2",0.25,IF(LEFT(O15,1)="3",0.5,IF(LEFT(O15,1)="4",1,"")))),"") -> 0.5 | R15: literatura | S15: 10.1002/ps.70227
A16: P015 | B16: 10 | C16: 2 - Usar com ressalva | D16: Dalbulus maidis | E16: Oviposição basal / ativação ovariana | F16: Não informado | G16: fertilidade | H16: > 80% por mais de 2 semanas (fêmeas hibernantes, sem machos) | I16: 80 | J16: % | N16: > 2 semanas | O16: 3 - Indireta | P16: =IFERROR(IF(LEFT(O16,1)="1",0.1,IF(LEFT(O16,1)="2",0.25,IF(LEFT(O16,1)="3",0.5,IF(LEFT(O16,1)="4",1,"")))),"") -> 0.5 | R16: literatura | S16: 10.1002/ps.70227
A17: P016 | B17: 10 | C17: 2 - Usar com ressalva | D17: Dalbulus maidis | E17: Oviposição basal / ativação ovariana | F17: Não informado | G17: estado_ovariano | H17: Ovários inativos mas fertilizados no inverno (quiescência reprodutiva) | N17: > 2 semanas | O17: 3 - Indireta | P17: =IFERROR(IF(LEFT(O17,1)="1",0.1,IF(LEFT(O17,1)="2",0.25,IF(LEFT(O17,1)="3",0.5,IF(LEFT(O17,1)="4",1,"")))),"") -> 0.5 | R17: literatura | S17: 10.1002/ps.70227
A18: P017 | B18: 11 | C18: 3 - Nao usar / corrigir | D18: Dalbulus maidis | E18: dsRNase-2 | F18: In vitro | G18: degradacao_saliva | H18: Total (~100%) (Secção 3.2. Analysis of Dmai-dsRNases transcript levels and dsRNA degradation in different tissues) | N18: 12 h | O18: 1 - Direta | P18: =IFERROR(IF(LEFT(O18,1)="1",0.1,IF(LEFT(O18,1)="2",0.25,IF(LEFT(O18,1)="3",0.5,IF(LEFT(O18,1)="4",1,"")))),"") -> 0.1 | Q18: nao | R18: literatura | S18: 10.1016/j.pest2023.105618bp. | T18: Beatriz Venancio | U18: 46276
A19: P018 | B19: 12 | C19: 2 - Usar com ressalva | D19: Dalbulus maidis | E19: V-ATPase B | F19: Oral - Dieta artificial | G19: sobrevivencia / concentração dsRNA | H19: ~16% e 0,5 μg/μL (500 ng/μL), respectivamente | I19: 16 e 500 | J19: % e ng/μL | N19: 4 dias | O19: 1 - Direta | P19: =IFERROR(IF(LEFT(O19,1)="1",0.1,IF(LEFT(O19,1)="2",0.25,IF(LEFT(O19,1)="3",0.5,IF(LEFT(O19,1)="4",1,"")))),"") -> 0.1 | Q19: sim | R19: literatura | S19: 10.1101/2021.09.29.462424 | T19: Beatriz Venancio | U19: 46276 | V19: Sobrevivência reduzida
A20: P019 | B20: 12 | C20: 2 - Usar com ressalva | D20: Dalbulus maidis | E20: V-ATPase B | F20: Dieta artificial | G20: deformacao_asa | H20: Alta significância | N20: 4 dias | O20: 1 - Direta | P20: =IFERROR(IF(LEFT(O20,1)="1",0.1,IF(LEFT(O20,1)="2",0.25,IF(LEFT(O20,1)="3",0.5,IF(LEFT(O20,1)="4",1,"")))),"") -> 0.1 | Q20: sim | R20: literatura | S20: 10.1101/2021.09.29.462424 | T20: Beatriz Venancio | U20: 46276 | V20: Deformação de asas significativa
A21: P020 | B21: 13 | C21: 2 - Usar com ressalva | D21: Dalbulus maidis | E21: V-ATPase D | F21: Dieta artificial | G21: sobrevivencia | H21: ~18% | I21: 18 | J21: % | N21: 4 dias | O21: 1 - Direta | P21: =IFERROR(IF(LEFT(O21,1)="1",0.1,IF(LEFT(O21,1)="2",0.25,IF(LEFT(O21,1)="3",0.5,IF(LEFT(O21,1)="4",1,"")))),"") -> 0.1 | Q21: sim | R21: literatura | S21: 10.1101/2021.09.29.462424 | T21: Beatriz Venancio | U21: 46276 | V21: Sobrevivência reduzida
A22: P021 | B22: 13 | C22: 2 - Usar com ressalva | D22: Dalbulus maidis | E22: V-ATPase D | F22: Dieta artificial | G22: deformacao_asa | H22: Não significativa | N22: 4 dias | O22: 1 - Direta | P22: =IFERROR(IF(LEFT(O22,1)="1",0.1,IF(LEFT(O22,1)="2",0.25,IF(LEFT(O22,1)="3",0.5,IF(LEFT(O22,1)="4",1,"")))),"") -> 0.1 | Q22: sim | R22: literatura | S22: 10.1101/2021.09.29.462424 | T22: Beatriz Venancio | U22: 46276 | V22: Deformação de asas não significativa
A23: P022 | B23: 14 | C23: 2 - Usar com ressalva | D23: Dalbulus maidis | E23: V-ATPase B | F23: Dieta artificial | G23: knockdown_alvo | H23: Não significativo | N23: 2 dias | O23: 1 - Direta | P23: =IFERROR(IF(LEFT(O23,1)="1",0.1,IF(LEFT(O23,1)="2",0.25,IF(LEFT(O23,1)="3",0.5,IF(LEFT(O23,1)="4",1,"")))),"") -> 0.1 | Q23: sim | R23: literatura | S23: 10.1101/2021.09.29.462424 | T23: Beatriz Venancio | U23: 46276 | V23: Knockdown não significativo em 2 dias
A24: P023 | B24: 15 | C24: 2 - Usar com ressalva | D24: Dalbulus maidis | E24: Parasitismo natural de ovos | F24: Coleta de ovos sentinela em campo | G24: ovos_expostos | H24: aproximadamente 1600 ovos sentinela (Página 3 - Primeiro paragrafo) | I24: 1600 | N24: 72–96 h de exposição em campo; ovos com menos de 24 h | O24: 2 - Parcialmente direta | P24: =IFERROR(IF(LEFT(O24,1)="1",0.1,IF(LEFT(O24,1)="2",0.25,IF(LEFT(O24,1)="3",0.5,IF(LEFT(O24,1)="4",1,"")))),"") -> 0.25 | R24: literatura | S24: 10.1653/024.092.0316
A25: P024 | B25: 15 | C25: 2 - Usar com ressalva | D25: Dalbulus maidis | E25: Parasitismo natural de ovos | F25: Coleta de ovos sentinela em campo | G25: parasitoides_emergidos | H25: 923 vespas emergidas (Página 3 - Primeiro paragrafo) | I25: 923 | J25: vespas emergidas | N25: 72–96 h de exposição em campo; ovos com menos de 24 h | O25: 2 - Parcialmente direta | P25: =IFERROR(IF(LEFT(O25,1)="1",0.1,IF(LEFT(O25,1)="2",0.25,IF(LEFT(O25,1)="3",0.5,IF(LEFT(O25,1)="4",1,"")))),"") -> 0.25 | R25: literatura | S25: 10.1653/024.092.0316
A26: P025 | B26: 15 | C26: 2 - Usar com ressalva | D26: Dalbulus maidis | E26: Parasitismo natural de ovos | F26: Coleta de ovos sentinela em campo | G26: parasitoides_identificados | H26: 5 táxons: Anagrus breviphragma; Polynema sp.; Paracentrobia nr subflava; Aphelinoidea sp.; Pseudoligosita sp. | I26: 5 | J26: táxons: Anagrus breviphragma; Polynema sp.; Paracentrobia nr subflava; Aphelinoidea sp.; Pseudoligosita sp. | N26: 72–96 h de exposição em campo; ovos com menos de 24 h | O26: 2 - Parcialmente direta | P26: =IFERROR(IF(LEFT(O26,1)="1",0.1,IF(LEFT(O26,1)="2",0.25,IF(LEFT(O26,1)="3",0.5,IF(LEFT(O26,1)="4",1,"")))),"") -> 0.25 | R26: literatura | S26: 10.1653/024.092.0316
A27: P026 | B27: 15 | C27: 2 - Usar com ressalva | D27: Dalbulus maidis | E27: Parasitismo natural de ovos | F27: Coleta de ovos sentinela em campo | G27: local_coleta | H27: Zapopan e El Grullo, Jalisco, México | N27: 72–96 h de exposição em campo; ovos com menos de 24 h | O27: 2 - Parcialmente direta | P27: =IFERROR(IF(LEFT(O27,1)="1",0.1,IF(LEFT(O27,1)="2",0.25,IF(LEFT(O27,1)="3",0.5,IF(LEFT(O27,1)="4",1,"")))),"") -> 0.25 | R27: literatura | S27: 10.1653/024.092.0316
A28: P027 | B28: 15 | C28: 2 - Usar com ressalva | D28: Dalbulus maidis | E28: Parasitismo natural de ovos | F28: Coleta de ovos sentinela em campo | G28: distribuição_por_local | H28: El Grullo: 419 parasitoides; Zapopan: 504 parasitoides (Table 2) | N28: 72–96 h de exposição em campo; ovos com menos de 24 h | O28: 2 - Parcialmente direta | P28: =IFERROR(IF(LEFT(O28,1)="1",0.1,IF(LEFT(O28,1)="2",0.25,IF(LEFT(O28,1)="3",0.5,IF(LEFT(O28,1)="4",1,"")))),"") -> 0.25 | R28: literatura | S28: 10.1653/024.092.0316
